<?xml version="1.0"?>
<robot xmlns:xacro="http://www.ros.org/wiki/xacro"  name="ROBOT_PROJECT_VERSION_02">
<xacro:include filename="inertial_macros.xacro" />
    <material name="white">
        <color rgba="1 1 1 1" />
    </material>

    <material name="orange">
        <color rgba="1 0.3 0.1 1"/>
    </material>

    <material name="blue">
        <color rgba="0.2 0.2 1 1"/>
    </material>

    <material name="black">
        <color rgba="0 0 0 1"/>
    </material>
   
 <material name="red">
     <color rgba="1 0 0 1"/>
 </material>



<!-- Link -->
  <!-- BASE LINK -->
  <link name="base_link">
  </link>
    
  <!-- BASE_FOOTPRINT LINK -->

  <joint name="base_footprint_joint" type="fixed">
    <parent link="base_link"/>
    <child link="base_footprint"/>
    <origin xyz="0 0 0" rpy="0 0 0"/>
  </joint>

  <link name="base_footprint">
  </link>


<!-- Link 0(BODY PART) -->
 <link name="link_0">
    <visual>
      <geometry>
        <mesh filename="/root/ROBOT_PROJECT_02_ws/BODY_PART_Version3.dae" scale="1 1 1"/>
      </geometry>
    </visual>
    <collision>
      <geometry>
        <mesh filename="/root/ROBOT_PROJECT_02_ws/BODY_PART_Version3.dae" scale="1 1 1"/>
      </geometry>
    </collision>
    <xacro:inertial_box mass="6" x="0.480" y="0.500" z="0.">
        <origin xyz="0 0 0" rpy="0 0 0"/>
    </xacro:inertial_box>
  </link>
    <gazebo reference="link_0">
    <material>Gazebo/White</material>
    </gazebo>

<!-- Joint between base_link and link_0  -->
  <joint name="joint_0" type="fixed">
    <parent link="base_link"/>
    <child link="link_0"/>
    <origin xyz="0 0 0" rpy="0 0 0"/>  
  </joint>  

  <!-- Link 14(LEFT_BACK PART) -->
 <link name="link_14">
    <visual>
      <geometry>
        <mesh filename="/root/ROBOT_PROJECT_02_ws/Wheel_partV3.dae" scale="1 1 1"/>
      </geometry>
    </visual>
    <collision>
      <geometry>
        <mesh filename="/root/ROBOT_PROJECT_02_ws/Wheel_partV3.dae" scale="1 1 1"/>
      </geometry>
    </collision>
    <xacro:inertial_cylinder mass="4" length ="0.060" radius ="0.075" >
        <origin xyz="0 0 0" rpy="0 0 0"/>
    </xacro:inertial_cylinder>
  </link>
    <gazebo reference="link_0">
    <material>Gazebo/White</material>
    </gazebo>

  <!-- Joint between link_0 and link_14 -->
  <joint name="joint_14" type="continuous">
    <parent link="base_link"/>
    <child link="link_14"/>
    <origin xyz="-0.130194 0.208533 0.0" rpy="0 0 0"/>
    <axis xyz="0 1 0"/>
  </joint>



  <!-- Link 15(RIGHT_BACK PART) -->
 <link name="link_15">
    <visual>
      <geometry>
        <mesh filename="/root/ROBOT_PROJECT_02_ws/Wheel_partV3.dae" scale="1 1 1"/>
      </geometry>
    </visual>
    <collision>
      <geometry>
        <mesh filename="/root/ROBOT_PROJECT_02_ws/Wheel_partV3.dae" scale="1 1 1"/>
      </geometry>
    </collision>
    <xacro:inertial_cylinder mass="4" length ="0.060" radius ="0.075" >
        <origin xyz="0 0 0" rpy="0 0 0"/>
    </xacro:inertial_cylinder>
  </link>
    <gazebo reference="link_0">
    <material>Gazebo/White</material>
    </gazebo>

  <!-- Joint between link_0 and link_15 -->
  <joint name="joint_15" type="continuous">
    <parent link="base_link"/>
    <child link="link_15"/>
    <origin xyz="-0.130194 -0.211467 0.0" rpy="0 0 0"/>
    <axis xyz="0 1 0"/>
  </joint>

    <!-- Link 16(RIGHT_FRONT PART) -->
 <link name="link_16">
    <visual>
      <geometry>
        <mesh filename="/root/ROBOT_PROJECT_02_ws/Wheel_partV3.dae" scale="1 1 1"/>
      </geometry>
    </visual>
    <collision>
      <geometry>
        <mesh filename="/root/ROBOT_PROJECT_02_ws/Wheel_partV3.dae" scale="1 1 1"/>
      </geometry>
    </collision>
    <xacro:inertial_cylinder mass="4" length ="0.060" radius ="0.075" >
        <origin xyz="0 0 0" rpy="0 0 0"/>
    </xacro:inertial_cylinder>
  </link>
    <gazebo reference="link_0">
    <material>Gazebo/White</material>
    </gazebo>

  <!-- Joint between link_0 and link_16 -->
  <joint name="joint_16" type="continuous">
    <parent link="base_link"/>
    <child link="link_16"/>
    <origin xyz="0.080 -0.211467 0.0" rpy="0 0 0"/>
    <axis xyz="0 1 0"/>
  </joint>

      <!-- Link 17(LEFT_FRONT PART) -->
 <link name="link_17">
    <visual>
      <geometry>
        <mesh filename="/root/ROBOT_PROJECT_02_ws/Wheel_partV3.dae" scale="1 1 1"/>
      </geometry>
    </visual>
    <collision>
      <geometry>
        <mesh filename="/root/ROBOT_PROJECT_02_ws/Wheel_partV3.dae" scale="1 1 1"/>
      </geometry>
    </collision>
    <xacro:inertial_cylinder mass="4" length ="0.060" radius ="0.075" >
        <origin xyz="0 0 0" rpy="0 0 0"/>
    </xacro:inertial_cylinder>
  </link>
    <gazebo reference="link_0">
    <material>Gazebo/White</material>
    </gazebo>

  <!-- Joint between link_0 and link_17 -->
  <joint name="joint_17" type="continuous">
    <parent link="base_link"/>
    <child link="link_17"/>
    <origin xyz="0.080 0.208533 0.0" rpy="0 0 0"/>
    <axis xyz="0 1 0"/>
  </joint>

   <!--  Link 24 (ARM RIGHT)-->
  <link name="link_24">
    <visual>
      <geometry>
        <mesh filename="/root/ROBOT_PROJECT_02_ws/LINK_V3.dae" scale="1 1 1"/>
      </geometry>
    </visual>
    <collision>
      <geometry>
        <mesh filename="/root/ROBOT_PROJECT_02_ws/LINK_V3.dae" scale="1 1 1"/>
      </geometry>
    </collision>
    <xacro:inertial_box mass="0.8" x="0.18" y="0.028" z="0.085">
        <origin xyz="0 0 0" rpy="0 0 0"/>
    </xacro:inertial_box>
  </link>
    <gazebo reference="link_0">
    <material>Gazebo/White</material>
    </gazebo>
  

  <!-- Joint between link_0 and link_24 -->
  <joint name="joint_24" type="revolute">
    <parent link="base_link"/>
    <child link="link_24"/>
    <origin xyz="0.503 -0.166 0.079" rpy="0 0 0"/>
    <axis xyz="1 0 0"/>
    <limit effort="5.0" velocity="1.0" lower="-0.540" upper="0.540"/>
  </joint>

     <!--  Link 25 (ARM LEFT)-->
  <link name="link_25">
    <visual>
      <geometry>
        <mesh filename="/root/ROBOT_PROJECT_02_ws/LINK_V3.dae" scale="1 1 1"/>
      </geometry>
    </visual>
    <collision>
      <geometry>
        <mesh filename="/root/ROBOT_PROJECT_02_ws/LINK_V3.dae" scale="1 1 1"/>
      </geometry>
    </collision>
    <xacro:inertial_box mass="0.8" x="0.18" y="0.028" z="0.085">
        <origin xyz="0 0 0" rpy="0 0 0"/>
    </xacro:inertial_box>
  </link>
    <gazebo reference="link_0">
    <material>Gazebo/White</material>
    </gazebo>
  

   <!-- Joint between link_0 and link_25 -->
  <joint name="joint_25" type="revolute">
    <parent link="base_link"/>
    <child link="link_25"/>
    <origin xyz="0.503 0.166 0.079" rpy="0 0 0"/>
    <axis xyz="1 0 0"/>
    <limit effort="5.0" velocity="1.0" lower="-0.540" upper="0.540"/>
  </joint>

  <!-- Link 27 (Hydraulic right)-->
  <link name="link_27">
    <visual>
      <geometry>
        <mesh filename="/root/ROBOT_PROJECT_02_ws/HAND1_V3dae.dae" scale="1 1 1"/>
      </geometry>
    </visual>
    <collision>
      <geometry>
        <mesh filename="/root/ROBOT_PROJECT_02_ws/HAND1_V3dae.dae" scale="1 1 1"/>
      </geometry>
    </collision>
    <xacro:inertial_box mass="0.2" x="0.15" y="0.090" z="0.15">
        <origin xyz="0 0 0" rpy="0 0 0"/>
    </xacro:inertial_box>
  </link>
    <gazebo reference="link_0">
    <material>Gazebo/White</material>
    </gazebo>

  <!-- Joint between link_24 and link_27 -->
  <joint name="joint_27" type="prismatic">
    <parent link="link_24"/>
    <child link="link_27"/>
    <origin xyz="0.681 -0.159 0.028" rpy="0 0 0"/>
    <axis xyz="1 0 0"/>
   <limit lower="-0.2625" upper="0" effort="10.0" velocity="0.5"/>
   <dynamics damping="0.1" friction="0.05"/>
  </joint>

  <!-- Link 28 (Hydraulic left)-->
  <link name="link_28">
    <visual>
      <geometry>
        <mesh filename="/root/ROBOT_PROJECT_02_ws/HAND2_V3dae.dae" scale="1 1 1"/>
      </geometry>
    </visual>
    <collision>
      <geometry>
        <mesh filename="/root/ROBOT_PROJECT_02_ws/HAND2_V3dae.dae" scale="1 1 1"/>
      </geometry>
    </collision>
    <xacro:inertial_box mass="0.2" x="0.15" y="0.090" z="0.15">
        <origin xyz="0 0 0" rpy="0 0 0"/>
    </xacro:inertial_box>
  </link>
    <gazebo reference="link_0">
    <material>Gazebo/White</material>
    </gazebo>

  <!-- Joint between link_25 and link_28 -->
  <joint name="joint_28" type="prismatic">
    <parent link="link_25"/>
    <child link="link_28"/>
    <origin xyz="0.681 0.16 0.028" rpy="0 0 0"/>
    <axis xyz="1 0 0"/>
   <limit lower="-0.2625" upper="0" effort="10.0" velocity="0.5"/>
   <dynamics damping="0.1" friction="0.05"/>
  </joint>
</robot>
